Workbook
Name PowderIDs: 'Boulder Sample Log'!$R$5:$R$204
Name SampleIDs: 'Boulder Sample Log'!$E$5:$E$204

Sheet Dashboard
B2: SBMM OU1 — XRF Field Campaign Dashboard
B3: Tasks 2.1.6 & 2.1.7 — Surface XRF + Boulder Crushing + Depth/Heterogeneity + Powder | Status: COMPLETE
B5: TOTAL BOULDERS | D5: XRF READINGS | F5: POWDER SAMPLES | H5: VERIFICATION PASS
B6: =COUNTA('Boulder Sample Log'!A5:A204) -> 146 | D6: =SUM('Boulder Sample Log'!P5:P204) -> 1768 | F6: =COUNTIF('Lab Samples'!G$5:G$48,"Powder")&" / 21" -> 21 / 21 | H6: =IFERROR(COUNTIF('Daily Verification'!K6:K100,"Pass")/(COUNTIF('Daily Verification'!K6:K100,"Pass")+COUNTIF('Daily Verification'!K6:K100,"Fail")),0) -> 1
B10: Boulders & XRF by Area
B11: Area | C11: Boulders | D11: XRF Rdgs | E11: Powders | F11: Avg Hg (ppm) | G11: Avg As (ppm) | H11: Avg Sb (ppm) | I11: Avg Sb (ppm)
B12: SWRP | C12: =COUNTIF('Boulder Sample Log'!B$5:B$204,B12) -> 23 | D12: =SUMIF('Boulder Sample Log'!B$5:B$204,B12,'Boulder Sample Log'!P$5:P$204) -> 348 | E12: =COUNTIFS('Lab Samples'!C$5:C$48,B12,'Lab Samples'!G$5:G$48,"Powder") -> 8 | F12: =IFERROR(AVERAGEIFS('Boulder Sample Log'!Q$5:Q$204,'Boulder Sample Log'!B$5:B$204,B12,'Boulder Sample Log'!Q$5:Q$204,">0"),"-") -> 18.418333 | G12: =IFERROR(AVERAGEIFS('Boulder Sample Log'!R$5:R$204,'Boulder Sample Log'!B$5:B$204,B12,'Boulder Sample Log'!R$5:R$204,">0"),"-") -> 9.4075 | H12: =IFERROR(AVERAGEIFS('Boulder Sample Log'!Y$5:Y$204,'Boulder Sample Log'!B$5:B$204,B12,'Boulder Sample Log'!Y$5:Y$204,">0"),"-") -> 19.9
B13: NWRP | C13: =COUNTIF('Boulder Sample Log'!B$5:B$204,B13) -> 24 | D13: =SUMIF('Boulder Sample Log'!B$5:B$204,B13,'Boulder Sample Log'!P$5:P$204) -> 258 | E13: =COUNTIFS('Lab Samples'!C$5:C$48,B13,'Lab Samples'!G$5:G$48,"Powder") -> 1 | F13: =IFERROR(AVERAGEIFS('Boulder Sample Log'!Q$5:Q$204,'Boulder Sample Log'!B$5:B$204,B13,'Boulder Sample Log'!Q$5:Q$204,">0"),"-") -> 14.114783 | G13: =IFERROR(AVERAGEIFS('Boulder Sample Log'!R$5:R$204,'Boulder Sample Log'!B$5:B$204,B13,'Boulder Sample Log'!R$5:R$204,">0"),"-") -> 10.254783 | H13: =IFERROR(AVERAGEIFS('Boulder Sample Log'!Y$5:Y$204,'Boulder Sample Log'!B$5:B$204,B13,'Boulder Sample Log'!Y$5:Y$204,">0"),"-") -> 15.504286
B14: NWWRP | C14: =COUNTIF('Boulder Sample Log'!B$5:B$204,B14) -> 15 | D14: =SUMIF('Boulder Sample Log'!B$5:B$204,B14,'Boulder Sample Log'!P$5:P$204) -> 162 | E14: =COUNTIFS('Lab Samples'!C$5:C$48,B14,'Lab Samples'!G$5:G$48,"Powder") -> 1 | F14: =IFERROR(AVERAGEIFS('Boulder Sample Log'!Q$5:Q$204,'Boulder Sample Log'!B$5:B$204,B14,'Boulder Sample Log'!Q$5:Q$204,">0"),"-") -> 11.780667 | G14: =IFERROR(AVERAGEIFS('Boulder Sample Log'!R$5:R$204,'Boulder Sample Log'!B$5:B$204,B14,'Boulder Sample Log'!R$5:R$204,">0"),"-") -> 1.6433333 | H14: =IFERROR(AVERAGEIFS('Boulder Sample Log'!Y$5:Y$204,'Boulder Sample Log'!B$5:B$204,B14,'Boulder Sample Log'!Y$5:Y$204,">0"),"-") -> 0.53
B15: NWP | C15: =COUNTIF('Boulder Sample Log'!B$5:B$204,B15) -> 17 | D15: =SUMIF('Boulder Sample Log'!B$5:B$204,B15,'Boulder Sample Log'!P$5:P$204) -> 208 | E15: =COUNTIFS('Lab Samples'!C$5:C$48,B15,'Lab Samples'!G$5:G$48,"Powder") -> 4 | F15: =IFERROR(AVERAGEIFS('Boulder Sample Log'!Q$5:Q$204,'Boulder Sample Log'!B$5:B$204,B15,'Boulder Sample Log'!Q$5:Q$204,">0"),"-") -> 43.485882 | G15: =IFERROR(AVERAGEIFS('Boulder Sample Log'!R$5:R$204,'Boulder Sample Log'!B$5:B$204,B15,'Boulder Sample Log'!R$5:R$204,">0"),"-") -> 4.5607692 | H15: =IFERROR(AVERAGEIFS('Boulder Sample Log'!Y$5:Y$204,'Boulder Sample Log'!B$5:B$204,B15,'Boulder Sample Log'!Y$5:Y$204,">0"),"-") -> 2.78
B16: WRD | C16: =COUNTIF('Boulder Sample Log'!B$5:B$204,B16) -> 29 | D16: =SUMIF('Boulder Sample Log'!B$5:B$204,B16,'Boulder Sample Log'!P$5:P$204) -> 316 | E16: =COUNTIFS('Lab Samples'!C$5:C$48,B16,'Lab Samples'!G$5:G$48,"Powder") -> 2 | F16: =IFERROR(AVERAGEIFS('Boulder Sample Log'!Q$5:Q$204,'Boulder Sample Log'!B$5:B$204,B16,'Boulder Sample Log'!Q$5:Q$204,">0"),"-") -> 18.962692 | G16: =IFERROR(AVERAGEIFS('Boulder Sample Log'!R$5:R$204,'Boulder Sample Log'!B$5:B$204,B16,'Boulder Sample Log'!R$5:R$204,">0"),"-") -> 25.791333 | H16: =IFERROR(AVERAGEIFS('Boulder Sample Log'!Y$5:Y$204,'Boulder Sample Log'!B$5:B$204,B16,'Boulder Sample Log'!Y$5:Y$204,">0"),"-") -> 48.263333
B17: WWRP | C17: =COUNTIF('Boulder Sample Log'!B$5:B$204,B17) -> 15 | D17: =SUMIF('Boulder Sample Log'!B$5:B$204,B17,'Boulder Sample Log'!P$5:P$204) -> 214 | E17: =COUNTIFS('Lab Samples'!C$5:C$48,B17,'Lab Samples'!G$5:G$48,"Powder") -> 2 | F17: =IFERROR(AVERAGEIFS('Boulder Sample Log'!Q$5:Q$204,'Boulder Sample Log'!B$5:B$204,B17,'Boulder Sample Log'!Q$5:Q$204,">0"),"-") -> 262.43667 | G17: =IFERROR(AVERAGEIFS('Boulder Sample Log'!R$5:R$204,'Boulder Sample Log'!B$5:B$204,B17,'Boulder Sample Log'!R$5:R$204,">0"),"-") -> 43.215 | H17: =IFERROR(AVERAGEIFS('Boulder Sample Log'!Y$5:Y$204,'Boulder Sample Log'!B$5:B$204,B17,'Boulder Sample Log'!Y$5:Y$204,">0"),"-") -> 3.6966667
B18: DRA | C18: =COUNTIF('Boulder Sample Log'!B$5:B$204,B18) -> 23 | D18: =SUMIF('Boulder Sample Log'!B$5:B$204,B18,'Boulder Sample Log'!P$5:P$204) -> 262 | E18: =COUNTIFS('Lab Samples'!C$5:C$48,B18,'Lab Samples'!G$5:G$48,"Powder") -> 3 | F18: =IFERROR(AVERAGEIFS('Boulder Sample Log'!Q$5:Q$204,'Boulder Sample Log'!B$5:B$204,B18,'Boulder Sample Log'!Q$5:Q$204,">0"),"-") -> 31.185263 | G18: =IFERROR(AVERAGEIFS('Boulder Sample Log'!R$5:R$204,'Boulder Sample Log'!B$5:B$204,B18,'Boulder Sample Log'!R$5:R$204,">0"),"-") -> 17.4075 | H18: =IFERROR(AVERAGEIFS('Boulder Sample Log'!Y$5:Y$204,'Boulder Sample Log'!B$5:B$204,B18,'Boulder Sample Log'!Y$5:Y$204,">0"),"-") -> 73.355
B19: Site-wide AVG | C19: =SUM(C12:C18) -> 146 | D19: =SUM(D12:D18) -> 1768 | E19: =SUM(E12:E18) -> 21 | F19: =IFERROR(AVERAGEIFS('Boulder Sample Log'!Q$5:Q$204,'Boulder Sample Log'!Q$5:Q$204,">0"),"-") -> 49.580752 | G19: =IFERROR(AVERAGEIFS('Boulder Sample Log'!R$5:R$204,'Boulder Sample Log'!R$5:R$204,">0"),"-") -> 15.647864 | H19: =IFERROR(AVERAGEIFS('Boulder Sample Log'!Y$5:Y$204,'Boulder Sample Log'!Y$5:Y$204,">0"),"-") -> 26.668387
B22: Depth XRF (Heterogeneity) Profile | F22: Powder XRF Summary
B23: Boulders Profiled | C23: =COUNTIF('Boulder Selection Log'!P5:P50,"Complete") -> 26 | F23: Parent Powders | G23: =COUNTIF('Lab Samples'!G$5:G$48,"Powder") -> 21 | H23: of | I23: 21
B24: Total Depth Readings | C24: =COUNTA('Depth XRF Detail'!A5:A1000) -> 478 | F24: Field Duplicates | G24: =COUNTIF('Lab Samples'!G$5:G$48,"FD") -> 10 | H24: of | I24: 10
B25: WRD Shoreline Boulders | C25: =COUNTIF('Boulder Selection Log'!D5:D50,"Shoreline") -> 21 | F25: MS/MSD Pairs | G25: 6 | H25: of | I25: 7
B26: Primary 14 (depth) | C26: =COUNTIFS('Boulder Selection Log'!D5:D50,1,'Boulder Selection Log'!P5:P50,"Complete")+COUNTIFS('Boulder Selection Log'!D5:D50,2,'Boulder Selection Log'!P5:P50,"Complete") -> 4 | F26: Equipment Blanks | G26: =COUNTIF('Lab Samples'!G$5:G$48,"EB") -> 3 | H26: of | I26: 3
B28: Daily Verification (IARM 35NN) | F28: Notable Findings
B29: Total Verifications | C29: =COUNTIF('Daily Verification'!K6:K100,"Pass")+COUNTIF('Daily Verification'!K6:K100,"Fail") -> 64 | F29: • | G29: Highest avg Hg: WWRP area (262.4 ppm)
B30: Passes | C30: =COUNTIF('Daily Verification'!K6:K100,"Pass") -> 64 | F30: • | G30: Highest avg Sb: DRA area (73.4 ppm)
B31: Failures | C31: =COUNTIF('Daily Verification'!K6:K100,"Fail") -> 0 | F31: • | G31: Highest avg As: WWRP area (43.2 ppm)
B32: Pass Rate | C32: =IFERROR(C30/C29,0) -> 1 | F32: • | G32: Hottest single boulder: WWRP-G02-B2 (Hg max 23,796 ppm)
B34: Campaign Milestones
B35: Event | D35: Date(s) | F35: Notes
B36: Surface XRF Campaign Start | D36: 4/2/2026 | F36: SWRP first day
B37: Surface XRF Complete | D37: 5/1/2026 | F37: NWWRP G11/G12/G13 + NWP G13 wrapped surface
B38: Depth XRF Start | D38: 5/4/2026 | F38: NWP-G13 proof-of-concept profile
B39: ERRG Crushing Start | D39: 5/4/2026 | F39: NWP-G13 cut as test
B40: ERRG Crushing Complete | D40: 5/7/2026 | F40: 14/14 primary cracked (NWP-G12 swapped in for WWRP-G15)
B41: WRD Shoreline Depth XRF | D41: 5/7 – 5/8/2026 | F41: 21 shoreline boulders profiled (off primary 14)
B42: Final Powder Collection | D42: 5/8/2026 | F42: DRA-G01, DRA-G10, SWRP-G08 (Mo)
B43: Powder XRF Complete | D43: 5/8/2026 | F43: All 14 primary parents — X500456 Mining mode
B44: Campaign End | D44: 5/8/2026 | F44: Day 24 — XRF data collection complete
B46: Tracker generated by Jacobs SBMM team — see Sample Tracker for full detail

Sheet Boulder Sample Log
A1: SBMM OU1 — XRF Boulder Sample Tracker
A2: Tasks 2.1.6 & 2.1.7 — Surface XRF & Powder Collection | Updated Daily | MASTER SHEET — other tabs auto-populate from here
A3: ID | B3: Location | F3: GPS | I3: Boulder Info | L3: XRF Data | S3: Powder / Lab | V3: Documentation
A4: Date | B4: Area Code | C4: Grid # | D4: Boulder # | E4: Sample ID | F4: Northing | G4: Easting | H4: Elev (ft) | I4: Type (H/F) | J4: Rind? (Y/N) | K4: Rind Thick (in) | L4: Surface Rdg # Start | M4: Surface Rdg # End | N4: Powder Rdg # Start | O4: Powder Rdg # End | P4: # of Rdgs | Q4: Avg Hg (ppm) | R4: Avg As (ppm) | S4: Powder (Y/N) | T4: Powder Sample ID | U4: Lab Sample # | V4: NCD Filename | W4: Photo Count | X4: Notes | Y4: Avg Sb (ppm)
A5: 46114 | B5: SWRP | C5: 12 | D5: B1 | E5: =IF(B5="","","SBM-"&B5&"-G"&TEXT(C5,"00")&"-"&D5) -> SBM-SWRP-G12-B1 | F5: 4317025 | G5: 529256.2 | H5: 406.7 | I5: H | J5: Y | L5: 2 | M5: 16 | N5: 17 | O5: 19 | P5: =IF(L5="","",(M5-L5+1)+IF(N5="",0,O5-N5+1)) -> 18 | Q5: 13.74 | R5: 0 | S5: Y | T5: SBM-SWRP-G12-HB-PR | V5: SBM-SWRP-G12.ncd | W5: 0 | X5: Hard andesite; MS+MSD collected | Y5: 3.72
A6: 46114 | B6: SWRP | C6: 12 | D6: B2 | E6: =IF(B6="","","SBM-"&B6&"-G"&TEXT(C6,"00")&"-"&D6) -> SBM-SWRP-G12-B2 | F6: 4317020.5 | G6: 529267.1 | H6: 411.7 | I6: F | J6: Y | L6: 20 | M6: 34 | N6: 35 | O6: 37 | P6: =IF(L6="","",(M6-L6+1)+IF(N6="",0,O6-N6+1)) -> 18 | Q6: 75.85 | R6: 0 | S6: Y | T6: SBM-SWRP-G12-FB-PR | V6: SBM-SWRP-G12.ncd | W6: 0 | X6: Friable; Hg hot spot Spot 3 (164-178 ppm) | Y6: 0
A7: 46115 | B7: SWRP | C7: 14 | D7: B1 | E7: =IF(B7="","","SBM-"&B7&"-G"&TEXT(C7,"00")&"-"&D7) -> SBM-SWRP-G14-B1 | F7: 4317010.5 | G7: 529230.8 | H7: 406.7 | I7: H | J7: Y | L7: 48 | M7: 62 | N7: 78 | O7: 80 | P7: =IF(L7="","",(M7-L7+1)+IF(N7="",0,O7-N7+1)) -> 18 | Q7: 5.33 | R7: 0 | S7: Y | T7: SBM-SWRP-G14-HB-PR | V7: SBM-SWRP-G14 & G15.ncd | W7: 0 | X7: Hard; MS+MSD collected | Y7: 0
A8: 46115 | B8: SWRP | C8: 14 | D8: B2 | E8: =IF(B8="","","SBM-"&B8&"-G"&TEXT(C8,"00")&"-"&D8) -> SBM-SWRP-G14-B2 | F8: 4316986.5 | G8: 529226.8 | H8: 433.5 | I8: F | L8: 63 | M8: 77 | N8: 81 | O8: 83 | P8: =IF(L8="","",(M8-L8+1)+IF(N8="",0,O8-N8+1)) -> 18 | Q8: 8.13 | R8: 2.59 | S8: Y | T8: SBM-SWRP-G14-FB-PR | V8: SBM-SWRP-G14 & G15.ncd | W8: 0 | X8: Friable; only boulder w/ As detection | Y8: 0
A9: 46115 | B9: SWRP | C9: 15 | D9: B1 | E9: =IF(B9="","","SBM-"&B9&"-G"&TEXT(C9,"00")&"-"&D9) -> SBM-SWRP-G15-B1 | F9: 4316974 | G9: 529294.5 | H9: 447.3 | I9: H | L9: 84 | M9: 100 | N9: 116 | O9: 118 | P9: =IF(L9="","",(M9-L9+1)+IF(N9="",0,O9-N9+1)) -> 20 | Q9: 3.44 | R9: 0 | S9: Y | T9: SBM-SWRP-G15-HB-PR | V9: SBM-SWRP-G14 & G15.ncd | W9: 0 | X9: Hard; aborted rdg 86-87 (excluded) | Y9: 13.08
A10: 46115 | B10: SWRP | C10: 15 | D10: B2 | E10: =IF(B10="","","SBM-"&B10&"-G"&TEXT(C10,"00")&"-"&D10) -> SBM-SWRP-G15-B2 | F10: 4316994.5 | G10: 529256.2 | H10: 437.5 | I10: F | J10: Y | L10: 101 | M10: 115 | N10: 119 | O10: 121 | P10: =IF(L10="","",(M10-L10+1)+IF(N10="",0,O10-N10+1)) -> 18 | Q10: 26.55 | R10: 0 | S10: Y | T10: SBM-SWRP-G15-FB-PR | V10: SBM-SWRP-G14 & G15.ncd | W10: 0 | X10: Friable; Hg hot spot Spot 4 (~80 ppm); FD collected | Y10: 93.09
A11: 46118 | B11: SWRP | C11: 13 | D11: B1 | E11: =IF(B11="","","SBM-"&B11&"-G"&TEXT(C11,"00")&"-"&D11) -> SBM-SWRP-G13-B1 | F11: 4317074.5 | G11: 529375.5 | H11: 417.5 | I11: H | J11: Y | K11: 0.01 | L11: 128 | M11: 142 | P11: =IF(L11="","",(M11-L11+1)+IF(N11="",0,O11-N11+1)) -> 15 | Q11: 0 | R11: 0 | S11: N | V11: SBM-SWRP-G10-G13+WWRP-G07_20260406.ncd | W11: 0 | X11: Hard; Hg+As all <LOD | Y11: 0
A12: 46118 | B12: SWRP | C12: 13 | D12: B2 | E12: =IF(B12="","","SBM-"&B12&"-G"&TEXT(C12,"00")&"-"&D12) -> SBM-SWRP-G13-B2 | F12: 4317074.5 | G12: 529380 | H12: 424.9 | I12: F | J12: Y | K12: 0.01 | L12: 143 | M12: 159 | P12: =IF(L12="","",(M12-L12+1)+IF(N12="",0,O12-N12+1)) -> 17 | Q12: 0 | R12: 25 | S12: N | V12: SBM-SWRP-G10-G13+WWRP-G07_20260406.ncd | W12: 0 | X12: Friable; Rdg 157 dup + 158 abort excluded; As avg 25 | Y12: 0
A13: 46118 | B13: WWRP | C13: 7 | D13: B1 | E13: =IF(B13="","","SBM-"&B13&"-G"&TEXT(C13,"00")&"-"&D13) -> SBM-WWRP-G07-B1 | F13: 4316997.5 | G13: 528719.4 | H13: 408.7 | I13: H | J13: Y | K13: 0.01 | L13: 160 | M13: 174 | P13: =IF(L13="","",(M13-L13+1)+IF(N13="",0,O13-N13+1)) -> 15 | Q13: 14.98 | R13: 353.99 | S13: N | V13: SBM-SWRP-G10-G13+WWRP-G07_20260406.ncd | W13: 0 | X13: Hard; HIGH As avg 354 ppm | Y13: 0
A14: 46118 | B14: WWRP | C14: 7 | D14: B2 | E14: =IF(B14="","","SBM-"&B14&"-G"&TEXT(C14,"00")&"-"&D14) -> SBM-WWRP-G07-B2 | I14: F | J14: Y | K14: 0.01 | L14: 175 | M14: 189 | P14: =IF(L14="","",(M14-L14+1)+IF(N14="",0,O14-N14+1)) -> 15 | Q14: 6.36 | R14: 0 | S14: N | V14: SBM-SWRP-G10-G13+WWRP-G07_20260406.ncd | W14: 0 | X14: Friable; As <LOD; no GPS from XRF | Y14: 1.25
A15: 46118 | B15: SWRP | C15: 10 | D15: B1 | E15: =IF(B15="","","SBM-"&B15&"-G"&TEXT(C15,"00")&"-"&D15) -> SBM-SWRP-G10-B1 | F15: 4317039 | G15: 529081.6 | H15: 401.6 | I15: H | J15: Y | K15: 0.01 | L15: 190 | M15: 205 | P15: =IF(L15="","",(M15-L15+1)+IF(N15="",0,O15-N15+1)) -> 16 | Q15: 14.58 | R15: 5.76 | S15: N | V15: SBM-SWRP-G10-G13+WWRP-G07_20260406.ncd | W15: 0 | X15: Hard only; Rdg 192 trigger mishap excluded; Rdg 205 listed as P on form | Y15: 0
A16: 46119 | B16: SWRP | C16: 10 | D16: B2 | E16: =IF(B16="","","SBM-"&B16&"-G"&TEXT(C16,"00")&"-"&D16) -> SBM-SWRP-G10-B2 | F16: 4317046.5 | G16: 529077.2 | H16: 408.1 | I16: F | J16: N | L16: 219 | M16: 233 | P16: =IF(L16="","",(M16-L16+1)+IF(N16="",0,O16-N16+1)) -> 15 | Q16: 0 | R16: 8.1 | S16: N | V16: SBM-SWRP-G04-G10-G11_20260407.ncd | W16: 0 | X16: Friable andesite | Y16: 4.05
A17: 46119 | B17: SWRP | C17: 11 | D17: B2 | E17: =IF(B17="","","SBM-"&B17&"-G"&TEXT(C17,"00")&"-"&D17) -> SBM-SWRP-G11-B2 | F17: 4317065.5 | G17: 529177 | H17: 428.3 | I17: F | J17: N | L17: 234 | M17: 249 | P17: =IF(L17="","",(M17-L17+1)+IF(N17="",0,O17-N17+1)) -> 16 | Q17: 4.8 | R17: 19.9 | S17: N | V17: SBM-SWRP-G04-G10-G11_20260407.ncd | W17: 0 | X17: Friable; Rdg 246 kept (94.1s, near complete) | Y17: 2.16
A18: 46119 | B18: SWRP | C18: 11 | D18: B1 | E18: =IF(B18="","","SBM-"&B18&"-G"&TEXT(C18,"00")&"-"&D18) -> SBM-SWRP-G11-B1 | F18: 4317068 | G18: 529177.4 | H18: 426.4 | I18: H | J18: N | L18: 250 | M18: 265 | P18: =IF(L18="","",(M18-L18+1)+IF(N18="",0,O18-N18+1)) -> 16 | Q18: 3.7 | R18: 1.3 | S18: N | V18: SBM-SWRP-G04-G10-G11_20260407.ncd | W18: 0 | X18: Hard andesite; Rdg 262 trigger mishap removed | Y18: 0
A19: 46119 | B19: SWRP | C19: 4 | D19: B1 | E19: =IF(B19="","","SBM-"&B19&"-G"&TEXT(C19,"00")&"-"&D19) -> SBM-SWRP-G04-B1 | F19: 4317144 | G19: 529280.3 | H19: 417.7 | I19: H | J19: N | L19: 266 | M19: 280 | P19: =IF(L19="","",(M19-L19+1)+IF(N19="",0,O19-N19+1)) -> 15 | Q19: 1.3 | R19: 0 | S19: N | V19: SBM-SWRP-G04-G10-G11_20260407.ncd | W19: 0 | X19: Hard; GPS from Rdg 277 (266 missing GPS) | Y19: 0
A20: 46119 | B20: SWRP | C20: 4 | D20: B2 | E20: =IF(B20="","","SBM-"&B20&"-G"&TEXT(C20,"00")&"-"&D20) -> SBM-SWRP-G04-B2 | F20: 4316902.5 | G20: 529236.3 | H20: 204.3 | I20: F | J20: N | L20: 281 | M20: 296 | P20: =IF(L20="","",(M20-L20+1)+IF(N20="",0,O20-N20+1)) -> 16 | Q20: 0 | R20: 0 | S20: N | V20: SBM-SWRP-G04-G10-G11_20260407.ncd | W20: 0 | X20: Friable; Rdg 295 trigger mishap removed; XRF clock out of sync | Y20: 3.3
A21: 46120 | B21: WWRP | C21: 14 | D21: B1 | E21: =IF(B21="","","SBM-"&B21&"-G"&TEXT(C21,"00")&"-"&D21) -> SBM-WWRP-G14-B1 | F21: 4316902 | G21: 528663.69 | H21: 403.5 | I21: H | J21: Y | K21: 0.01 | L21: 308 | M21: 323 | P21: =IF(L21="","",(M21-L21+1)+IF(N21="",0,O21-N21+1)) -> 16 | Q21: 2.1 | R21: 0 | S21: N | V21: SBM-WWRP-G09-G13-G14-G15_20260408.ncd | W21: 0 | X21: Hard; Rdg 318 trigger mishap removed; only 1 boulder located in grid | Y21: 0
A22: 46120 | B22: WWRP | C22: 15 | D22: B2 | E22: =IF(B22="","","SBM-"&B22&"-G"&TEXT(C22,"00")&"-"&D22) -> SBM-WWRP-G15-B2 | F22: 4316848.5 | G22: 528692.44 | H22: 404.39999 | I22: F | J22: Y | K22: 0.01 | L22: 324 | M22: 338 | P22: =IF(L22="","",(M22-L22+1)+IF(N22="",0,O22-N22+1)) -> 15 | Q22: 74.2 | R22: 0.5 | S22: N | V22: SBM-WWRP-G09-G13-G14-G15_20260408.ncd | W22: 0 | X22: Friable; highest Hg avg in campaign | Y22: 0
A23: 46120 | B23: WWRP | C23: 15 | D23: B1 | E23: =IF(B23="","","SBM-"&B23&"-G"&TEXT(C23,"00")&"-"&D23) -> SBM-WWRP-G15-B1 | F23: 4316826.5 | G23: 528724.81 | H23: 425.29999 | I23: H | J23: Y | K23: 0.01 | L23: 339 | M23: 355 | P23: =IF(L23="","",(M23-L23+1)+IF(N23="",0,O23-N23+1)) -> 17 | Q23: 15.1 | R23: 5 | S23: N | V23: SBM-WWRP-G09-G13-G14-G15_20260408.ncd | W23: 0 | X23: Hard; Rdg 343 (1.8s) and 353 (60.1s) removed | Y23: 0
A24: 46120 | B24: WWRP | C24: 9 | D24: B1 | E24: =IF(B24="","","SBM-"&B24&"-G"&TEXT(C24,"00")&"-"&D24) -> SBM-WWRP-G09-B1 | F24: 4316892.5 | G24: 528582.44 | H24: 181.7 | I24: H | J24: Y | K24: 0.01 | L24: 356 | M24: 388 | P24: =IF(L24="","",(M24-L24+1)+IF(N24="",0,O24-N24+1)) -> 33 | Q24: 44.7 | R24: 9.6 | S24: N | V24: SBM-WWRP-G09-G13-G14-G15_20260408.ncd | W24: 0 | X24: Hard; rain break after Rdg 357, resumed at 374; Rdg 358 discarded, 384+385 trigger mishaps removed; only 1 boulder located | Y24: 0
A25: 46120 | B25: WWRP | C25: 13 | D25: B1 | E25: =IF(B25="","","SBM-"&B25&"-G"&TEXT(C25,"00")&"-"&D25) -> SBM-WWRP-G13-B1 | F25: 4316887 | G25: 528599.62 | H25: 405.20001 | I25: H | J25: Y | K25: 0.01 | L25: 359 | M25: 373 | P25: =IF(L25="","",(M25-L25+1)+IF(N25="",0,O25-N25+1)) -> 15 | Q25: 1.7 | R25: 1.1 | S25: N | V25: SBM-WWRP-G09-G13-G14-G15_20260408.ncd | W25: 0 | X25: Hard; sampled during G9 rain break; Nolen Brown assisted; only 1 boulder located | Y25: 0
A26: 46121 | B26: SWRP | C26: 7 | D26: B2 | E26: =IF(B26="","","SBM-"&B26&"-G"&TEXT(C26,"00")&"-"&D26) -> SBM-SWRP-G07-B2 | F26: 4317107.5 | G26: 529210.2 | H26: 410.8 | I26: F | J26: Y | K26: 0.01 | L26: 401 | M26: 415 | P26: =IF(L26="","",(M26-L26+1)+IF(N26="",0,O26-N26+1)) -> 15 | Q26: 32.7 | R26: 0.5 | S26: N | V26: SBM-SWRP-G01-G05-G07_20260409.ncd | W26: 0 | X26: 5x3 protocol; Spot 1 elevated Hg (72-154 ppm); radius 1.0 ft | Y26: 0
A27: 46121 | B27: SWRP | C27: 7 | D27: B1 | E27: =IF(B27="","","SBM-"&B27&"-G"&TEXT(C27,"00")&"-"&D27) -> SBM-SWRP-G07-B1 | F27: 4317100.5 | G27: 529218.2 | H27: 413.4 | I27: H | J27: Y | K27: 0.01 | L27: 416 | M27: 425 | P27: =IF(L27="","",(M27-L27+1)+IF(N27="",0,O27-N27+1)) -> 10 | Q27: 6.8 | R27: 1.8 | S27: N | V27: SBM-SWRP-G01-G05-G07_20260409.ncd | W27: 0 | X27: 5x2 protocol; radius 2.0 ft | Y27: 0
A28: 46121 | B28: SWRP | C28: 1 | D28: B1 | E28: =IF(B28="","","SBM-"&B28&"-G"&TEXT(C28,"00")&"-"&D28) -> SBM-SWRP-G01-B1 | F28: 4317164 | G28: 529321.4 | H28: 416.8 | I28: H | J28: Y | K28: 0.01 | L28: 426 | M28: 435 | P28: =IF(L28="","",(M28-L28+1)+IF(N28="",0,O28-N28+1)) -> 10 | Q28: 0 | R28: 0 | S28: N | V28: SBM-SWRP-G01-G05-G07_20260409.ncd | W28: 0 | X28: 5x2 protocol; all readings <LOD; radius 1.0 ft | Y28: 0
A29: 46121 | B29: SWRP | C29: 1 | D29: B2 | E29: =IF(B29="","","SBM-"&B29&"-G"&TEXT(C29,"00")&"-"&D29) -> SBM-SWRP-G01-B2 | F29: 4317170 | G29: 529319.4 | H29: 416.3 | I29: F | J29: Y | K29: 0.01 | L29: 436 | M29: 445 | P29: =IF(L29="","",(M29-L29+1)+IF(N29="",0,O29-N29+1)) -> 10 | Q29: 1.3 | R29: 0.2 | S29: N | V29: SBM-SWRP-G01-G05-G07_20260409.ncd | W29: 0 | X29: 5x2 protocol; radius 2.0 ft | Y29: 0
A30: 46121 | B30: SWRP | C30: 5 | D30: B1 | E30: =IF(B30="","","SBM-"&B30&"-G"&TEXT(C30,"00")&"-"&D30) -> SBM-SWRP-G05-B1 | F30: 4316908.5 | G30: 529188.7 | H30: 439.8 | I30: H | J30: Y | K30: 0.01 | L30: 446 | M30: 464 | P30: =IF(L30="","",(M30-L30+1)+IF(N30="",0,O30-N30+1)) -> 19 | Q30: 2.6 | R30: 14.9 | S30: N | V30: SBM-SWRP-G01-G05-G07_20260409.ncd | W30: 0 | X30: 5x3 protocol; Rdg 449 sulphur rock, 451+452 mishaps, 461 no contact; 1 boulder located; radius 2.0 ft | Y30: 0
A31: 46125 | B31: SWRP | C31: 9 | D31: B1 | E31: =IF(B31="","","SBM-"&B31&"-G"&TEXT(C31,"00")&"-"&D31) -> SBM-SWRP-G09-B1 | F31: 4317099 | G31: 529373.9 | H31: 1334.6 | I31: H | J31: Y | K31: 0.01 | L31: 498 | M31: 507 | P31: =IF(L31="","",(M31-L31+1)+IF(N31="",0,O31-N31+1)) -> 10 | Q31: 1.77 | R31: 0 | S31: N | V31: SBM-SWRP_G9_G2_G8+WWRP_G3_G6.ncd | W31: 0 | X31: 5x2 protocol; 1 boulder located; operator: Michelle Gill | Y31: 0
A32: 46125 | B32: SWRP | C32: 2 | D32: B1 | E32: =IF(B32="","","SBM-"&B32&"-G"&TEXT(C32,"00")&"-"&D32) -> SBM-SWRP-G02-B1 | F32: 4317201 | G32: 529379.4 | H32: 1303.8 | I32: H | J32: Y | K32: 0.01 | L32: 508 | M32: 521 | P32: =IF(L32="","",(M32-L32+1)+IF(N32="",0,O32-N32+1)) -> 14 | Q32: 0.73 | R32: 31.05 | S32: N | V32: SBM-SWRP_G9_G2_G8+WWRP_G3_G6.ncd | W32: 0 | X32: Mixed 5x2/5x3; Rdg 512+516+518 mishaps; 1 boulder located; operator: Michelle Gill | Y32: 0
... A44: 46126 | B44: WRD | C44: 15 | D44: B2 | E44: =IF(B44="","","SBM-"&B44&"-G"&TEXT(C44,"00")&"-"&D44) -> SBM-WRD-G15-B2 | F44: 4317101.5 | G44: 528804.2 | H44: 1344.8 | I44: F | J44: Y | K44: 0.01 | L44: 652 | M44: 664 | P44: =IF(L44="","",(M44-L44+1)+IF(N44="",0,O44-N44+1)) -> 13 | Q44: 2.8 | R44: 10.66 | S44: N | V44: SBM-WWRP-G4-G6-G2-G5_WRD-G15.ncd | W44: 0 | X44: Mixed; Rdg 655+662+665 discarded (mishaps); Rdg 664 Fe=0 flagged | Y44: 2.2
A45: 46127 | B45: WRD | C45: 14 | D45: B1 | E45: =IF(B45="","","SBM-"&B45&"-G"&TEXT(C45,"00")&"-"&D45) -> SBM-WRD-G14-B1 | F45: 4317208.5 | G45: 528727.94 | H45: 1287.4 | I45: H | J45: Y | K45: 0.01 | L45: 670 | M45: 679 | P45: =IF(L45="","",(M45-L45+1)+IF(N45="",0,O45-N45+1)) -> 10 | Q45: 73.08 | R45: 11.68 | S45: N | V45: SBM-WRD-G14-G13-G11-G10.ncd | W45: 0 | Y45: 0
A46: 46127 | B46: WRD | C46: 14 | D46: B2 | E46: =IF(B46="","","SBM-"&B46&"-G"&TEXT(C46,"00")&"-"&D46) -> SBM-WRD-G14-B2 | F46: 4317210.5 | G46: 528743.62 | H46: 1355.3 | I46: F | J46: Y | K46: 0.01 | L46: 680 | M46: 690 | P46: =IF(L46="","",(M46-L46+1)+IF(N46="",0,O46-N46+1)) -> 11 | Q46: 7.56 | R46: 0 | S46: N | V46: SBM-WRD-G14-G13-G11-G10.ncd | W46: 0 | Y46: 0
A47: 46127 | B47: WRD | C47: 13 | D47: B1 | E47: =IF(B47="","","SBM-"&B47&"-G"&TEXT(C47,"00")&"-"&D47) -> SBM-WRD-G13-B1 | F47: 4317254 | G47: 528740.44 | H47: 1358.9 | I47: H | J47: Y | K47: 0.01 | L47: 691 | M47: 700 | P47: =IF(L47="","",(M47-L47+1)+IF(N47="",0,O47-N47+1)) -> 10 | Q47: 0.27 | R47: 0 | S47: N | V47: SBM-WRD-G14-G13-G11-G10.ncd | W47: 0 | Y47: 0
A48: 46127 | B48: WRD | C48: 11 | D48: B1 | E48: =IF(B48="","","SBM-"&B48&"-G"&TEXT(C48,"00")&"-"&D48) -> SBM-WRD-G11-B1 | F48: 4317104 | G48: 528545 | H48: 1313.3 | I48: H | J48: Y | K48: 0.01 | L48: 701 | M48: 710 | P48: =IF(L48="","",(M48-L48+1)+IF(N48="",0,O48-N48+1)) -> 10 | Q48: 1.14 | R48: 0 | S48: N | V48: SBM-WRD-G14-G13-G11-G10.ncd | W48: 0 | Y48: 0
A49: 46127 | B49: WRD | C49: 11 | D49: B2 | E49: =IF(B49="","","SBM-"&B49&"-G"&TEXT(C49,"00")&"-"&D49) -> SBM-WRD-G11-B2 | F49: 4317108 | G49: 528542.81 | H49: 1304.5 | I49: H | J49: Y | K49: 0.01 | L49: 711 | M49: 720 | P49: =IF(L49="","",(M49-L49+1)+IF(N49="",0,O49-N49+1)) -> 10 | Q49: 0.8 | R49: 0 | S49: N | V49: SBM-WRD-G14-G13-G11-G10.ncd | W49: 0 | Y49: 0
A50: 46127 | B50: WRD | C50: 10 | D50: B1 | E50: =IF(B50="","","SBM-"&B50&"-G"&TEXT(C50,"00")&"-"&D50) -> SBM-WRD-G10-B1 | F50: 4317137.5 | G50: 528546.06 | H50: 1326.1 | I50: H | J50: Y | K50: 0.01 | L50: 721 | M50: 731 | P50: =IF(L50="","",(M50-L50+1)+IF(N50="",0,O50-N50+1)) -> 11 | Q50: 0.3 | R50: 0 | S50: N | V50: SBM-WRD-G14-G13-G11-G10.ncd | W50: 0 | X50: Rdg 730 discarded (Fe<LOD) | Y50: 0
A51: 46128 | B51: WRD | C51: 10 | D51: B2 | E51: =IF(B51="","","SBM-"&B51&"-G"&TEXT(C51,"00")&"-"&D51) -> SBM-WRD-G10-B2 | F51: 4317155.5 | G51: 528542.94 | H51: 1293.3 | I51: H | J51: Y | K51: 0.01 | L51: 740 | M51: 751 | P51: =IF(L51="","",(M51-L51+1)+IF(N51="",0,O51-N51+1)) -> 12 | Q51: 1.31 | R51: 0 | S51: N | V51: SBM-WRD-G6-G7-G8-G9-G10-G12.ncd | W51: 0 | X51: Rdg 748 trigger (33s); Rdg 746 discarded (Fe<LOD) | Y51: 0
...

Sheet XRF Readings Detail
A1: XRF Individual Reading Log
A2: Pick Sample ID → Date auto-fills from Boulder Sample Log
A3: Identification | F3: Element Results | N3: Instrument
A4: Sample ID | B4: Date (auto) | C4: XRF Rdg # | D4: Reading Type | E4: Spot # | F4: Hg (ppm) | G4: As (ppm) | H4: Pb (ppm) | I4: Fe (ppm) | J4: Mn (ppm) | K4: S (ppm) | L4: Zn (ppm) | M4: Cu (ppm) | N4: Duration (sec) | O4: # Filters | P4: Notes | Q4: XRF S/N
A5: SBM-SWRP-G12-B1 | B5: =IFERROR(INDEX('Boulder Sample Log'!A$5:A$204,MATCH(A5,'Boulder Sample Log'!E$5:E$204,0)),"") -> 46114 | C5: 2 | D5: Surface | E5: 1 | F5: 4.4 | G5: <LOD | H5: 5.79 | I5: 26141.29 | J5: 350.81 | K5: 9305.54 | L5: 35.93 | M5: 10.19 | N5: 120.6 | O5: 4 | Q5: X501203
A6: SBM-SWRP-G12-B1 | B6: =IFERROR(INDEX('Boulder Sample Log'!A$5:A$204,MATCH(A6,'Boulder Sample Log'!E$5:E$204,0)),"") -> 46114 | C6: 3 | D6: Surface | E6: 1 | F6: 10.08 | G6: <LOD | H6: 9.88 | I6: 31370.69 | J6: 450.63 | K6: 3101.66 | L6: 34.14 | M6: 5.91 | N6: 120.6 | O6: 4 | Q6: X501203
A7: SBM-SWRP-G12-B1 | B7: =IFERROR(INDEX('Boulder Sample Log'!A$5:A$204,MATCH(A7,'Boulder Sample Log'!E$5:E$204,0)),"") -> 46114 | C7: 4 | D7: Surface | E7: 1 | F7: 5.46 | G7: <LOD | H7: 8.6 | I7: 31760.4 | J7: 364.91 | K7: 11103.9 | L7: 47.85 | M7: 5.9 | N7: 120.6 | O7: 4 | Q7: X501203
A8: SBM-SWRP-G12-B1 | B8: =IFERROR(INDEX('Boulder Sample Log'!A$5:A$204,MATCH(A8,'Boulder Sample Log'!E$5:E$204,0)),"") -> 46114 | C8: 5 | D8: Surface | E8: 2 | F8: <LOD | G8: <LOD | H8: 4.67 | I8: 33871.19 | J8: 512.15 | K8: 1829.2 | L8: 37.31 | M8: 9.32 | N8: 120.4 | O8: 4 | Q8: X501203
A9: SBM-SWRP-G12-B1 | B9: =IFERROR(INDEX('Boulder Sample Log'!A$5:A$204,MATCH(A9,'Boulder Sample Log'!E$5:E$204,0)),"") -> 46114 | C9: 6 | D9: Surface | E9: 2 | F9: 48.44 | G9: <LOD | H9: 4.83 | I9: 36168.13 | J9: 1995.06 | K9: 28837.54 | L9: 101.51 | M9: 14.51 | N9: 120.5 | O9: 4 | Q9: X501203
A10: SBM-SWRP-G12-B1 | B10: =IFERROR(INDEX('Boulder Sample Log'!A$5:A$204,MATCH(A10,'Boulder Sample Log'!E$5:E$204,0)),"") -> 46114 | C10: 7 | D10: Surface | E10: 2 | F10: 9.56 | G10: <LOD | H10: 9.88 | I10: 28289.14 | J10: 383.92 | K10: 9457.1 | L10: 36.6 | M10: 14.88 | N10: 120.4 | O10: 4 | Q10: X501203
A11: SBM-SWRP-G12-B1 | B11: =IFERROR(INDEX('Boulder Sample Log'!A$5:A$204,MATCH(A11,'Boulder Sample Log'!E$5:E$204,0)),"") -> 46114 | C11: 8 | D11: Surface | E11: 3 | F11: <LOD | G11: <LOD | H11: 6.55 | I11: 42506.76 | J11: 1258.15 | K11: 6270.34 | L11: 42.16 | M11: 16.55 | N11: 120.4 | O11: 4 | Q11: X501203
A12: SBM-SWRP-G12-B1 | B12: =IFERROR(INDEX('Boulder Sample Log'!A$5:A$204,MATCH(A12,'Boulder Sample Log'!E$5:E$204,0)),"") -> 46114 | C12: 9 | D12: Surface | E12: 3 | F12: 6.17 | G12: <LOD | H12: 8.96 | I12: 34397.96 | J12: 421.92 | K12: 5260.86 | L12: 46.72 | M12: 17.37 | N12: 120.5 | O12: 4 | Q12: X501203
A13: SBM-SWRP-G12-B1 | B13: =IFERROR(INDEX('Boulder Sample Log'!A$5:A$204,MATCH(A13,'Boulder Sample Log'!E$5:E$204,0)),"") -> 46114 | C13: 10 | D13: Surface | E13: 3 | F13: 5.99 | G13: <LOD | H13: 6.75 | I13: 30778.17 | J13: 395.8 | K13: 11560.28 | L13: 33.65 | M13: 8.18 | N13: 120.4 | O13: 4 | Q13: X501203
A14: SBM-SWRP-G12-B1 | B14: =IFERROR(INDEX('Boulder Sample Log'!A$5:A$204,MATCH(A14,'Boulder Sample Log'!E$5:E$204,0)),"") -> 46114 | C14: 11 | D14: Surface | E14: 4 | F14: 19.08 | G14: <LOD | H14: 6.07 | I14: 30223.72 | J14: <LOD | K14: 18289.84 | L14: <LOD | M14: <LOD | N14: 120.4 | O14: 4 | Q14: X501203
A15: SBM-SWRP-G12-B1 | B15: =IFERROR(INDEX('Boulder Sample Log'!A$5:A$204,MATCH(A15,'Boulder Sample Log'!E$5:E$204,0)),"") -> 46114 | C15: 12 | D15: Surface | E15: 4 | F15: 6.97 | G15: <LOD | H15: 7.94 | I15: 27823.93 | J15: 375.82 | K15: 12337.52 | L15: 32.37 | M15: 18.67 | N15: 120.5 | O15: 4 | Q15: X501203
A16: SBM-SWRP-G12-B1 | B16: =IFERROR(INDEX('Boulder Sample Log'!A$5:A$204,MATCH(A16,'Boulder Sample Log'!E$5:E$204,0)),"") -> 46114 | C16: 13 | D16: Surface | E16: 4 | F16: 2.82 | G16: <LOD | H16: 6.5 | I16: 45214.65 | J16: 1167.05 | K16: 6241.55 | L16: 46.33 | M16: 16 | N16: 120.4 | O16: 4 | Q16: X501203
A17: SBM-SWRP-G12-B1 | B17: =IFERROR(INDEX('Boulder Sample Log'!A$5:A$204,MATCH(A17,'Boulder Sample Log'!E$5:E$204,0)),"") -> 46114 | C17: 14 | D17: Surface | E17: 5 | F17: 12.59 | G17: <LOD | H17: 6.05 | I17: 45975.91 | J17: 401.99 | K17: 12383.45 | L17: 41.49 | M17: 21.92 | N17: 120.3 | O17: 4 | Q17: X501203
A18: SBM-SWRP-G12-B1 | B18: =IFERROR(INDEX('Boulder Sample Log'!A$5:A$204,MATCH(A18,'Boulder Sample Log'!E$5:E$204,0)),"") -> 46114 | C18: 15 | D18: Surface | E18: 5 | F18: 32.66 | G18: <LOD | H18: 6.17 | I18: 37341.72 | J18: 1170.19 | K18: 32405.24 | L18: 68.3 | M18: 8.38 | N18: 120.7 | O18: 4 | Q18: X501203
A19: SBM-SWRP-G12-B1 | B19: =IFERROR(INDEX('Boulder Sample Log'!A$5:A$204,MATCH(A19,'Boulder Sample Log'!E$5:E$204,0)),"") -> 46114 | C19: 16 | D19: Surface | E19: 5 | F19: 14.35 | G19: <LOD | H19: 5.47 | I19: 52586.05 | J19: 1124.99 | K19: 6540.37 | L19: 85.9 | M19: 44.13 | N19: 120.3 | O19: 4 | Q19: X501203
A20: SBM-SWRP-G12-B1 | B20: =IFERROR(INDEX('Boulder Sample Log'!A$5:A$204,MATCH(A20,'Boulder Sample Log'!E$5:E$204,0)),"") -> 46114 | C20: 17 | D20: Powder | E20: P | F20: <LOD | G20: <LOD | H20: <LOD | I20: 22640.14 | J20: 425.48 | K20: 1891.14 | L20: 21.2 | M20: <LOD | N20: 120.4 | O20: 4 | P20: SBM-SWRP-G12-HB-PR | Q20: X501203
A21: SBM-SWRP-G12-B1 | B21: =IFERROR(INDEX('Boulder Sample Log'!A$5:A$204,MATCH(A21,'Boulder Sample Log'!E$5:E$204,0)),"") -> 46114 | C21: 18 | D21: Powder | E21: P | F21: 3 | G21: <LOD | H21: 4.77 | I21: 27067.32 | J21: 552.05 | K21: 3214.15 | L21: 33.91 | M21: 4.85 | N21: 120.1 | O21: 4 | P21: SBM-SWRP-G12-HB-PR | Q21: X501203
A22: SBM-SWRP-G12-B1 | B22: =IFERROR(INDEX('Boulder Sample Log'!A$5:A$204,MATCH(A22,'Boulder Sample Log'!E$5:E$204,0)),"") -> 46114 | C22: 19 | D22: Powder | E22: P | F22: <LOD | G22: <LOD | H22: 4.92 | I22: 26538.34 | J22: 547.55 | K22: 3325.85 | L22: 31.92 | M22: 7.16 | N22: 120.4 | O22: 4 | P22: SBM-SWRP-G12-HB-PR | Q22: X501203
A23: SBM-SWRP-G12-B2 | B23: =IFERROR(INDEX('Boulder Sample Log'!A$5:A$204,MATCH(A23,'Boulder Sample Log'!E$5:E$204,0)),"") -> 46114 | C23: 20 | D23: Surface | E23: 1 | F23: 5.51 | G23: <LOD | H23: 17.53 | I23: 32516.49 | J23: 503.23 | K23: 1418.38 | L23: 28.61 | M23: 4.55 | N23: 120.5 | O23: 4 | Q23: X501203
A24: SBM-SWRP-G12-B2 | B24: =IFERROR(INDEX('Boulder Sample Log'!A$5:A$204,MATCH(A24,'Boulder Sample Log'!E$5:E$204,0)),"") -> 46114 | C24: 21 | D24: Surface | E24: 1 | F24: <LOD | G24: <LOD | H24: 9.51 | I24: 36634.33 | J24: 447.57 | K24: 1194.09 | L24: 29.94 | M24: 10.73 | N24: 120.3 | O24: 4 | Q24: X501203
A25: SBM-SWRP-G12-B2 | B25: =IFERROR(INDEX('Boulder Sample Log'!A$5:A$204,MATCH(A25,'Boulder Sample Log'!E$5:E$204,0)),"") -> 46114 | C25: 22 | D25: Surface | E25: 1 | F25: <LOD | G25: <LOD | H25: 7.58 | I25: 32304.81 | J25: 392.8 | K25: 1193.97 | L25: 30.45 | M25: 8.4 | N25: 120.2 | O25: 4 | Q25: X501203
A26: SBM-SWRP-G12-B2 | B26: =IFERROR(INDEX('Boulder Sample Log'!A$5:A$204,MATCH(A26,'Boulder Sample Log'!E$5:E$204,0)),"") -> 46114 | C26: 23 | D26: Surface | E26: 2 | F26: 3.64 | G26: <LOD | H26: 8.07 | I26: 31763.87 | J26: 474.79 | K26: 2118.13 | L26: 59.21 | M26: 15.16 | N26: 122.8 | O26: 4 | Q26: X501203
A27: SBM-SWRP-G12-B2 | B27: =IFERROR(INDEX('Boulder Sample Log'!A$5:A$204,MATCH(A27,'Boulder Sample Log'!E$5:E$204,0)),"") -> 46114 | C27: 24 | D27: Surface | E27: 2 | F27: <LOD | G27: <LOD | H27: <LOD | I27: <LOD | J27: 417.58 | K27: 3039.23 | L27: <LOD | M27: <LOD | N27: 123.9 | O27: 4 | Q27: X501203
A28: SBM-SWRP-G12-B2 | B28: =IFERROR(INDEX('Boulder Sample Log'!A$5:A$204,MATCH(A28,'Boulder Sample Log'!E$5:E$204,0)),"") -> 46114 | C28: 25 | D28: Surface | E28: 2 | F28: 2.47 | G28: <LOD | H28: 7.41 | I28: 32270.59 | J28: 384.11 | K28: 3427.39 | L28: 52.39 | M28: 11.6 | N28: 120.7 | O28: 4 | Q28: X501203
A29: SBM-SWRP-G12-B2 | B29: =IFERROR(INDEX('Boulder Sample Log'!A$5:A$204,MATCH(A29,'Boulder Sample Log'!E$5:E$204,0)),"") -> 46114 | C29: 26 | D29: Surface | E29: 3 | F29: 164.15 | G29: <LOD | H29: 7.78 | I29: 22918.85 | J29: <LOD | K29: 22013.09 | L29: <LOD | M29: <LOD | N29: 120.6 | O29: 4 | Q29: X501203
A30: SBM-SWRP-G12-B2 | B30: =IFERROR(INDEX('Boulder Sample Log'!A$5:A$204,MATCH(A30,'Boulder Sample Log'!E$5:E$204,0)),"") -> 46114 | C30: 27 | D30: Surface | E30: 3 | F30: 174.54 | G30: <LOD | H30: 8.42 | I30: 27010.91 | J30: <LOD | K30: 25680.51 | L30: <LOD | M30: 4.76 | N30: 122.8 | O30: 4 | Q30: X501203
A31: SBM-SWRP-G12-B2 | B31: =IFERROR(INDEX('Boulder Sample Log'!A$5:A$204,MATCH(A31,'Boulder Sample Log'!E$5:E$204,0)),"") -> 46114 | C31: 28 | D31: Surface | E31: 3 | F31: 177.69 | G31: <LOD | H31: 8.95 | I31: 22545.52 | J31: <LOD | K31: 29995.67 | L31: 4.52 | M31: 5.38 | N31: 123 | O31: 4 | Q31: X501203
A32: SBM-SWRP-G12-B2 | B32: =IFERROR(INDEX('Boulder Sample Log'!A$5:A$204,MATCH(A32,'Boulder Sample Log'!E$5:E$204,0)),"") -> 46114 | C32: 29 | D32: Surface | E32: 4 | F32: <LOD | G32: <LOD | H32: 7.81 | I32: 30418.21 | J32: 350.13 | K32: 2902.59 | L32: 53.96 | M32: 7.29 | N32: 120.4 | O32: 4 | Q32: X501203
A33: SBM-SWRP-G12-B2 | B33: =IFERROR(INDEX('Boulder Sample Log'!A$5:A$204,MATCH(A33,'Boulder Sample Log'!E$5:E$204,0)),"") -> 46114 | C33: 30 | D33: Surface | E33: 4 | F33: <LOD | G33: <LOD | H33: 7.27 | I33: 29266.96 | J33: 409.95 | K33: 2207.5 | L33: 47.08 | M33: 11.35 | N33: 120.3 | O33: 4 | Q33: X501203
A34: SBM-SWRP-G12-B2 | B34: =IFERROR(INDEX('Boulder Sample Log'!A$5:A$204,MATCH(A34,'Boulder Sample Log'!E$5:E$204,0)),"") -> 46114 | C34: 31 | D34: Surface | E34: 4 | F34: 2.96 | G34: <LOD | H34: 6.17 | I34: 29373.69 | J34: 344.19 | K34: 2828.45 | L34: 52.21 | M34: 16.36 | N34: 120.7 | O34: 4 | Q34: X501203
A35: SBM-SWRP-G12-B2 | B35: =IFERROR(INDEX('Boulder Sample Log'!A$5:A$204,MATCH(A35,'Boulder Sample Log'!E$5:E$204,0)),"") -> 46114 | C35: 32 | D35: Surface | E35: 5 | F35: <LOD | G35: <LOD | H35: 6.42 | I35: 34124.82 | J35: 402.96 | K35: 4153.36 | L35: 39.7 | M35: 8.09 | N35: 120.5 | O35: 4 | Q35: X501203
A36: SBM-SWRP-G12-B2 | B36: =IFERROR(INDEX('Boulder Sample Log'!A$5:A$204,MATCH(A36,'Boulder Sample Log'!E$5:E$204,0)),"") -> 46114 | C36: 33 | D36: Surface | E36: 5 | F36: <LOD | G36: <LOD | H36: 7.17 | I36: 32161.64 | J36: 363.02 | K36: 3241.43 | L36: 34.77 | M36: 8.43 | N36: 120.2 | O36: 4 | Q36: X501203
A37: SBM-SWRP-G12-B2 | B37: =IFERROR(INDEX('Boulder Sample Log'!A$5:A$204,MATCH(A37,'Boulder Sample Log'!E$5:E$204,0)),"") -> 46114 | C37: 34 | D37: Surface | E37: 5 | F37: <LOD | G37: <LOD | H37: 8.21 | I37: 31840.16 | J37: 425.53 | K37: 4783.91 | L37: 46.3 | M37: 11.18 | N37: 120.5 | O37: 4 | Q37: X501203
A38: SBM-SWRP-G12-B2 | B38: =IFERROR(INDEX('Boulder Sample Log'!A$5:A$204,MATCH(A38,'Boulder Sample Log'!E$5:E$204,0)),"") -> 46114 | C38: 35 | D38: Powder | E38: P | F38: <LOD | G38: <LOD | H38: 5.58 | I38: 29301.25 | J38: 475.54 | K38: <LOD | L38: 34.22 | M38: 12.79 | N38: 120.5 | O38: 4 | P38: SBM-SWRP-G12-FB-PR | Q38: X501203
A39: SBM-SWRP-G12-B2 | B39: =IFERROR(INDEX('Boulder Sample Log'!A$5:A$204,MATCH(A39,'Boulder Sample Log'!E$5:E$204,0)),"") -> 46114 | C39: 36 | D39: Powder | E39: P | F39: <LOD | G39: <LOD | H39: 6.82 | I39: 30599.96 | J39: 521.63 | K39: 330.79 | L39: 36.64 | M39: <LOD | N39: 120.5 | O39: 4 | P39: SBM-SWRP-G12-FB-PR | Q39: X501203
A40: SBM-SWRP-G12-B2 | B40: =IFERROR(INDEX('Boulder Sample Log'!A$5:A$204,MATCH(A40,'Boulder Sample Log'!E$5:E$204,0)),"") -> 46114 | C40: 37 | D40: Powder | E40: P | F40: <LOD | G40: <LOD | H40: 9.82 | I40: 32295.12 | J40: 563.18 | K40: 197.4 | L40: 39 | M40: 10.5 | N40: 120.3 | O40: 4 | P40: SBM-SWRP-G12-FB-PR | Q40: X501203
...

Sheet Lab Samples
A1: Powder / Lab Sample Chain of Custody & Results
A2: Pick Powder Sample ID → Parent info auto-fills
A3: Sample Info | H3: Shipping / Laboratory | L3: Lab Results
A4: Powder Sample ID | B4: Parent Boulder ID (auto) | C4: Area (auto) | D4: Grid (auto) | E4: Date Collected (auto) | F4: Time Collected | G4: Sample Type | H4: Date Shipped | I4: Lab Name | J4: COC / Lab ID | K4: Date Results Received | L4: Lab Hg (ppm) | M4: Lab As (ppm) | N4: Lab Pb (ppm) | O4: Notes
A5: SBM-SWRP-RP-G12-ICP-HB | B5: SBM-SWRP-G12-B1 | C5: SWRP | D5: 12 | G5: Powder | O5: Prior campaign
A6: SBM-SWRP-RP-G12-ICP-FB | B6: SBM-SWRP-G12-B1 | C6: SWRP | D6: 12 | G6: Powder | O6: Prior campaign
A7: SBM-SWRP-RP-G14-ICP-HB | B7: SBM-SWRP-G14-B1 | C7: SWRP | D7: 14 | G7: Powder | O7: Prior campaign
A8: SBM-SWRP-RP-G14-ICP-FB | B8: SBM-SWRP-G14-B1 | C8: SWRP | D8: 14 | G8: Powder | O8: Prior campaign
A9: SBM-SWRP-RP-G15-ICP-HB | B9: SBM-SWRP-G15-B1 | C9: SWRP | D9: 15 | G9: Powder | O9: Prior campaign
A10: SBM-SWRP-RP-G15-ICP-FB | B10: SBM-SWRP-G15-B1 | C10: SWRP | D10: 15 | G10: Powder | O10: Prior campaign
A11: SBM-SWRP-RP-G15-ICP-FB-FD | B11: SBM-SWRP-G15-B1 | C11: SWRP | D11: 15 | G11: FD | O11: FD of SWRP-G15-FB
A12: SBM-SWRP-RP-G15-ICP-HB-MS | B12: SBM-SWRP-G15-B1 | C12: SWRP | D12: 15 | G12: MS | O12: MS of SWRP-G15-HB
A13: SBM-SWRP-RP-G15-ICP-HB-MSD | B13: SBM-SWRP-G15-B1 | C13: SWRP | D13: 15 | G13: MSD | O13: MSD of SWRP-G15-HB
A14: SBM-SWRP-RP-G13-ICP-HB | B14: SBM-SWRP-G13-B1 | C14: SWRP | D14: 13 | G14: Powder | O14: Prior campaign
A15: SBM-EB076 | F15: 0.66666667 | G15: EB | O15: EB for prior SWRP campaign powders
A16: SBM-WWRP-RP-G02-ICP-FB | B16: SBM-WWRP-G02-B2 | C16: WWRP | D16: 2 | E16: 46148 | F16: 0.44791667 | G16: Powder
A17: SBM-WWRP-RP-G02-ICP-FB-MS | B17: SBM-WWRP-G02-B2 | C17: WWRP | D17: 2 | E17: 46148 | F17: 0.44791667 | G17: MS | O17: MS of WWRP-G02-FB
A18: SBM-WWRP-RP-G02-ICP-FB-MSD | B18: SBM-WWRP-G02-B2 | C18: WWRP | D18: 2 | E18: 46148 | F18: 0.44791667 | G18: MSD | O18: MSD of WWRP-G02-FB
A19: SBM-DRA-RP-G13-ICP-FB | B19: SBM-DRA-G13-B2 | C19: DRA | D19: 13 | E19: 46148 | F19: 0.41388889 | G19: Powder
A20: SBM-DRA-RP-G13-ICP-FB-FD | B20: SBM-DRA-G13-B2 | C20: DRA | D20: 13 | E20: 46148 | F20: 0.41736111 | G20: FD | O20: FD of DRA-G13-FB
A21: SBM-WRD-RP-G05-ICP-FB | B21: SBM-WRD-G05-B2 | C21: WRD | D21: 5 | E21: 46148 | F21: 0.49027778 | G21: Powder
A22: SBM-WRD-RP-G05-ICP-FB-FD | B22: SBM-WRD-G05-B2 | C22: WRD | D22: 5 | E22: 46148 | F22: 0.49375 | G22: FD | O22: FD of WRD-G05-FB
A23: SBM-WRD-RP-G14-ICP-HB | B23: SBM-WRD-G14-B1 | C23: WRD | D23: 14 | E23: 46148 | F23: 0.47708333 | G23: Powder
A24: SBM-WRD-RP-G14-ICP-HB-MS | B24: SBM-WRD-G14-B1 | C24: WRD | D24: 14 | E24: 46148 | F24: 0.47708333 | G24: MS | O24: MS of WRD-G14-HB
A25: SBM-WRD-RP-G14-ICP-HB-MSD | B25: SBM-WRD-G14-B1 | C25: WRD | D25: 14 | E25: 46148 | F25: 0.47708333 | G25: MSD | O25: MSD of WRD-G14-HB
A26: SBM-WWRP-RP-G07-ICP-HB | B26: SBM-WWRP-G07-B1 | C26: WWRP | D26: 7 | E26: 46148 | F26: 0.42708333 | G26: Powder
A27: SBM-WWRP-RP-G07-ICP-HB-FD | B27: SBM-WWRP-G07-B1 | C27: WWRP | D27: 7 | E27: 46148 | F27: 0.43055556 | G27: FD | O27: FD of WWRP-G07-HB
A28: SBM-NWRP-RP-G12-ICP-FB | B28: SBM-NWRP-G12-B2 | C28: NWRP | D28: 12 | E28: 46148 | F28: 0.38819444 | G28: Powder
A29: SBM-NWRP-RP-G12-ICP-FB-FD | B29: SBM-NWRP-G12-B2 | C29: NWRP | D29: 12 | E29: 46148 | F29: 0.39166667 | G29: FD | O29: FD of NWRP-G12-FB
A30: SBM-NWP-RP-G14-ICP-HB | B30: SBM-NWP-G14-B1 | C30: NWP | D30: 14 | E30: 46149 | G30: Powder
A31: SBM-NWP-RP-G14-ICP-HB-FD | B31: SBM-NWP-G14-B1 | C31: NWP | D31: 14 | E31: 46149 | G31: FD | O31: FD of NWP-G14-HB
A32: SBM-NWP-RP-G12-ICP-HB | B32: SBM-NWP-G12-B1 | C32: NWP | D32: 12 | E32: 46149 | G32: Powder
A33: SBM-NWP-RP-G12-ICP-HB-FD | B33: SBM-NWP-G12-B1 | C33: NWP | D33: 12 | E33: 46149 | G33: FD | O33: FD of NWP-G12-HB
A34: SBM-NWP-RP-G13-ICP-HB | B34: SBM-NWP-G13-B1 | C34: NWP | D34: 13 | E34: 46149 | G34: Powder
A35: SBM-NWP-RP-G13-ICP-HB-MS | B35: SBM-NWP-G13-B1 | C35: NWP | D35: 13 | E35: 46149 | G35: MS | O35: MS of NWP-G13-HB
A36: SBM-NWP-RP-G13-ICP-HB-MSD | B36: SBM-NWP-G13-B1 | C36: NWP | D36: 13 | E36: 46149 | G36: MSD | O36: MSD of NWP-G13-HB
A37: SBM-NWP-RP-G08-ICP-HB | B37: SBM-NWP-G08-B1 | C37: NWP | D37: 8 | E37: 46149 | G37: Powder
A38: SBM-NWWRP-RP-G07-ICP-HB | B38: SBM-NWWRP-G07-B1 | C38: NWWRP | D38: 7 | E38: 46149 | G38: Powder
A39: SBM-NWWRP-RP-G07-ICP-HB-FD | B39: SBM-NWWRP-G07-B1 | C39: NWWRP | D39: 7 | E39: 46149 | G39: FD | O39: FD of NWWRP-G07-HB
A40: SBM-EB080 | E40: 46149 | F40: 0.66666667 | G40: EB | O40: EB for 5/7 powders: NWP-G14, G12, G13 (incl MS/MSD), G08, NWWRP-G07
...

Sheet Daily Verification
A1: Daily XRF Verification Log — IARM 35NN CRM
A2: Record AM & PM system check results against certified reference values
A3: Check Info | E3: Measured Values (compare to IARM 35NN cert) | K3: Result
A4: Date | B4: Time (AM/PM) | C4: Operator | D4: XRF Rdg # | E4: Measured Fe (%) | F4: Measured Cr (ppm) | G4: Measured Mo (ppm) | H4: Measured Mn (ppm) | I4: Measured Cu (ppm) | J4: Measured Ni (ppm) | K4: Pass / Fail | L4: Notes | M4: XRF S/N
A5: CERTIFIED VALUES → | E5: Fe: 97.22% | F5: Cr: 10860 | G5: Mo: 4780 | H5: Mn: 3310 | I5: Cu: 1740 | J5: Ni: 1250 | K5: ±20% RPD | M5: X501203
A6: 46114 | B6: AM | C6: Mo Sharif | D6: 1 | E6: 86.18 | F6: 8990.1 | G6: 4313.8 | H6: 2921.7 | I6: 1671.1 | J6: 1281.5 | K6: Pass | M6: X501203
A7: 46114 | B7: PM | C7: Mo Sharif | D7: 38 | E7: 85.18 | F7: 9330.3 | G7: 4224.1 | H7: 2868.6 | I7: 1672.8 | J7: 1428.7 | K7: Pass | M7: X501203
A8: 46115 | B8: AM | C8: Mo Sharif | D8: 47 | E8: 85.72 | F8: 8860.6 | G8: 4117.3 | H8: 2875.3 | I8: 1653.3 | J8: 1431.8 | K8: Pass | L8: 30s quick check | M8: X501203
A9: 46115 | B9: PM | C9: Mo Sharif | D9: 122 | E9: 87.01 | F9: 8988.6 | G9: 4211.3 | H9: 2789.6 | I9: 1666.4 | J9: 1351.7 | K9: Pass | M9: X501203
A10: 46118 | B10: AM | C10: Mo Sharif | D10: 127 | E10: 86.23 | F10: 8750.2 | G10: 4199.2 | H10: 2831.9 | I10: 1662 | J10: 1728.7 | K10: Pass | L10: 30s reading | M10: X501203
A11: 46118 | B11: PM | C11: Mo Sharif | D11: 207 | E11: 83.5 | F11: 8416 | G11: 1583 | H11: 1906 | I11: 1613 | J11: 3050 | K11: Pass | L11: 30s reading; Rdg 207 from field form | M11: X501203
A12: 46119 | B12: AM | C12: Mo Sharif | D12: 218 | E12: 86.08 | F12: 8774 | G12: 4155 | H12: 2805 | I12: 1688 | J12: 1478 | K12: Pass | M12: X501203
A13: 46119 | B13: PM | C13: Mo Sharif | D13: 297 | E13: 86.3 | F13: 8806 | G13: 4211 | H13: 2810 | I13: 1697 | J13: 1678 | K13: Pass | M13: X501203
A14: 46120 | B14: AM | C14: Mo Sharif | D14: 307 | E14: 86.61 | F14: 8778 | G14: 4248 | H14: 2777 | I14: 1742 | J14: 1343 | K14: Pass | M14: X501203
A15: 46120 | B15: PM | C15: Mo Sharif | D15: 389 | E15: 86.48 | F15: 8897 | G15: 4207 | H15: 2740 | I15: 1756 | J15: 1092 | K15: Pass | M15: X501203
A16: 46121 | B16: AM | C16: Mo Sharif | D16: 400 | E16: 86.12 | F16: 8770 | G16: 4213 | H16: 2773 | I16: 1679 | J16: 1366 | K16: Pass | M16: X501203
A17: 46121 | B17: PM | C17: Mo Sharif | D17: 465 | E17: 84.67 | F17: 9059 | G17: 3947 | H17: 2743 | I17: 1695 | J17: 1195 | K17: Pass | M17: X501203
A18: 46125 | B18: AM | C18: Mo Sharif | D18: 497 | E18: 86.59 | F18: 8774 | G18: 4169 | H18: 2761 | I18: 1708 | J18: 1386 | K18: Pass | M18: X501203
A19: 46125 | B19: PM | C19: Mo Sharif | D19: 580 | E19: 87.2 | F19: 8894 | G19: 4251 | H19: 2773 | I19: 1724 | J19: 1450 | K19: Pass | M19: X501203
A20: 46126 | B20: AM | C20: Michelle Gill | D20: 585 | E20: 86.98 | F20: 8766 | G20: 4267 | H20: 2903 | I20: 1620 | J20: 1300 | K20: Pass | M20: X501203
A21: 46126 | B21: PM | C21: Michelle Gill | D21: 666 | E21: 87.48 | F21: 8765 | G21: 4273 | H21: 2878 | I21: 1703 | J21: 1088 | K21: Pass | M21: X501203
A22: 46127 | B22: AM | C22: Mo Sharif | D22: 669 | E22: 86.21 | F22: 8736.1 | G22: 4166.9 | H22: 2746.1 | I22: 1659.2 | J22: 1217.1 | K22: Pass | M22: X501203
A23: 46127 | B23: PM | C23: Mo Sharif | D23: 732 | E23: 87.19 | F23: 8855.2 | G23: 4248.2 | H23: 2891.7 | I23: 1725.7 | J23: 1033.3 | K23: Pass | M23: X501203
... A50: 46143 | B50: AM | C50: M. Gil + T. Thomas | D50: 354 | E50: 86.7 | F50: 9699.3 | G50: 4728.17 | H50: 3884.07 | I50: 1196 | J50: 475.98 | K50: Pass | M50: X500456
A51: 46143 | B51: PM | C51: M. Gil + T. Thomas | D51: 435 | E51: 88.36 | F51: 9752.51 | G51: 5015.09 | H51: 3970.2 | I51: 1272.41 | J51: 587.82 | K51: Pass | L51: Rdg 434 was through-bag attempt; discarded. 435 is the redo out-of-bag. | M51: X500456
A52: 46146 | B52: AM | C52: M. Gil | D52: 438 | E52: 89.47 | F52: 9745.61 | G52: 5155.67 | H52: 3897.09 | I52: 1276.15 | J52: 487.19 | K52: Pass | L52: Ni low (within ±20% RPD) | M52: X500456
A53: 46146 | B53: PM | C53: M. Gil | D53: 488 | E53: 87.19 | F53: 9944.72 | G53: 4674.83 | H53: 3749.39 | I53: 1141.18 | J53: 514.9 | K53: Pass | L53: Ni low (within ±20% RPD) | M53: X500456
A54: 46147 | B54: AM | C54: M. Gil | D54: 491 | E54: 87.55 | F54: 9646.09 | G54: 4968.34 | H54: 3986.52 | I54: 1220.29 | J54: 711.61 | K54: Pass | M54: X500456
A55: 46147 | B55: PM | C55: M. Gil | D55: 548 | E55: 87.83 | F55: 9591.91 | G55: 4980.67 | H55: 3984.91 | I55: 1223.12 | J55: 438.12 | K55: Pass | L55: Ni low (within ±20% RPD) | M55: X500456
A56: 46147 | B56: AM | C56: A. Lineberger | D56: 1548 | E56: 86.65 | F56: 8826.18 | G56: 4178.26 | H56: 2869.14 | I56: 1662.8 | J56: 1158.83 | K56: Pass | M56: X501203
A57: 46147 | B57: PM | C57: A. Lineberger | D57: 1567 | E57: 85.41 | F57: 8757.3 | G57: 4124.28 | H57: 2815.16 | I57: 1631.92 | J57: 1069.52 | K57: Pass | M57: X501203
A58: 46148 | B58: AM | C58: A. Lineberger | D58: 551 | E58: 89.29 | F58: 9746.71 | G58: 5115.28 | H58: 3972.87 | I58: 1289.41 | J58: 496.99 | K58: Pass | L58: Powder XRF day (Aerial) | M58: X500456
A59: 46148 | B59: PM | C59: A. Lineberger | D59: 574 | E59: 88.48 | F59: 9625.75 | G59: 4972.81 | H59: 3829.61 | I59: 1306.78 | J59: 445.52 | K59: Pass | M59: X500456
A60: 46148 | B60: AM | C60: C. Mochrie | D60: 1570 | E60: 86.72 | F60: 8701.54 | G60: 4188.04 | H60: 2892.78 | I60: 1691.95 | J60: 1297.87 | K60: Pass | L60: Mine Building XRF (Christian + Michelle) | M60: X501203
A61: 46148 | B61: PM | C61: C. Mochrie | D61: 1632 | E61: 87.68 | F61: 8847.73 | G61: 4290.52 | H61: 2715.51 | I61: 1772.38 | J61: 1117.13 | K61: Pass | M61: X501203
A62: 46149 | B62: AM | C62: A. Lineberger | D62: 1635 | E62: 87.72 | F62: 8751.72 | G62: 4284.93 | H62: 2895.33 | I62: 1669.96 | J62: 1364.71 | K62: Pass | L62: WRD shoreline depth XRF day (gun clock off — actual 5/7) | M62: X501203
A63: 46149 | B63: PM | C63: A. Lineberger | D63: 1723 | E63: 86.11 | F63: 8854.15 | G63: 4156.74 | H63: 2730.09 | I63: 1659.16 | J63: 1223.69 | K63: Pass | M63: X501203
A64: 46149 | B64: AM | C64: M. Gil | D64: 577 | E64: 89.22 | F64: 9732.34 | G64: 5119.97 | H64: 3816.04 | I64: 1323.98 | J64: 633.85 | K64: Pass | L64: WRD shoreline depth XRF day | M64: X500456
A65: 46149 | B65: PM | C65: M. Gil | D65: 659 | E65: 88.84 | F65: 9627.95 | G65: 5047.57 | H65: 3959.01 | I65: 1289.49 | J65: 420.76 | K65: Pass | M65: X500456
A66: 46150 | B66: AM | C66: A. Lineberger | D66: 1728 | E66: 85.07 | F66: 9309.46 | G66: 4128.1 | H66: 2802.68 | I66: 1707.2 | J66: 1609.14 | K66: Pass | L66: Final field day; gun clock off (~14.5 hr behind real) | M66: X501203
...

Sheet Daily Field Log
A1: Daily Field Activity Log
A2: Enter Date → Boulder count, XRF readings, and Powder count auto-calculate from Boulder Sample Log
A3: Date | B3: Weather | C3: Area(s) Worked | D3: # Boulders (auto) | E3: # XRF Rdgs (auto) | F3: # Powder (auto) | G3: Equipment Issues | H3: NCD Files Uploaded | I3: Verification Pass? | J3: Notes / Summary
A4: 46114 | B4: Sunny, 70°F | C4: SWRP | D4: =IF(A4="","",COUNTIF('Boulder Sample Log'!A$5:A$204,A4)) -> 2 | E4: =IF(A4="","",SUMIF('Boulder Sample Log'!A$5:A$204,A4,'Boulder Sample Log'!P$5:P$204)) -> 36 | F4: =IF(A4="","",COUNTIFS('Boulder Sample Log'!A$5:A$204,A4,'Boulder Sample Log'!S$5:S$204,"Y")) -> 2 | G4: None | H4: Y | I4: Pass | J4: Day 1 main campaign; G12 sampled; 2 boulders; 1 EB
A5: 46115 | B5: Sunny, 70°F | C5: SWRP | D5: =IF(A5="","",COUNTIF('Boulder Sample Log'!A$5:A$204,A5)) -> 4 | E5: =IF(A5="","",SUMIF('Boulder Sample Log'!A$5:A$204,A5,'Boulder Sample Log'!P$5:P$204)) -> 74 | F5: =IF(A5="","",COUNTIFS('Boulder Sample Log'!A$5:A$204,A5,'Boulder Sample Log'!S$5:S$204,"Y")) -> 4 | G5: Aborted rdg 86-87 on G15 B1 | H5: Y | I5: Pass | J5: G14 + G15 sampled; 4 boulders; PD collected G15 B2
A6: 46118 | B6: Sunny, Clear, 79F | C6: SWRP, WWRP | D6: =IF(A6="","",COUNTIF('Boulder Sample Log'!A$5:A$204,A6)) -> 5 | E6: =IF(A6="","",SUMIF('Boulder Sample Log'!A$5:A$204,A6,'Boulder Sample Log'!P$5:P$204)) -> 78 | F6: =IF(A6="","",COUNTIFS('Boulder Sample Log'!A$5:A$204,A6,'Boulder Sample Log'!S$5:S$204,"Y")) -> 0 | G6: Rdg 158 abort; Rdg 201 <LOD; Rdg 192 short | H6: Y | I6: Pass | J6: G13+G10(H only)+WWRP G7; 5 boulders; no powder per John; Rdg 157 dup, 158 abort, 192 trigger mishap
A7: 46119 | B7: Sunny, Clear, 75F | C7: SWRP | D7: =IF(A7="","",COUNTIF('Boulder Sample Log'!A$5:A$204,A7)) -> 5 | E7: =IF(A7="","",SUMIF('Boulder Sample Log'!A$5:A$204,A7,'Boulder Sample Log'!P$5:P$204)) -> 78 | F7: =IF(A7="","",COUNTIFS('Boulder Sample Log'!A$5:A$204,A7,'Boulder Sample Log'!S$5:S$204,"Y")) -> 0 | G7: Rdg 262 trigger mishap (G11 B1); Rdg 295 trigger mishap (G04 B2); Rdg 246 kept (94.1s near-complete) | H7: Y | I7: Pass | J7: G10(F)+G11(H+F)+G04(H+F); 5 boulders; no powder; G04 B1 GPS from Rdg 277
A8: 46120 | B8: Sunny Clear to Overcast, 78F | C8: WWRP | D8: =IF(A8="","",COUNTIF('Boulder Sample Log'!A$5:A$204,A8)) -> 5 | E8: =IF(A8="","",SUMIF('Boulder Sample Log'!A$5:A$204,A8,'Boulder Sample Log'!P$5:P$204)) -> 96 | F8: =IF(A8="","",COUNTIFS('Boulder Sample Log'!A$5:A$204,A8,'Boulder Sample Log'!S$5:S$204,"Y")) -> 0 | G8: Rdg 318 (55s), 343 (1.8s), 353 (60s), 358 (discarded stray), 384 (52s), 385 (6.6s); rain break during G9 | H8: Y | I8: Pass | J8: G14(H)+G15(H+F)+G9(H)+G13(H); 5 boulders; no powder; G9 rain break; G13/G14/G9 only 1 boulder located; Nolen Brown assisted G13
A9: 46121 | B9: Overcast 56F to Sunny Clear 75F | C9: SWRP | D9: =IF(A9="","",COUNTIF('Boulder Sample Log'!A$5:A$204,A9)) -> 5 | E9: =IF(A9="","",SUMIF('Boulder Sample Log'!A$5:A$204,A9,'Boulder Sample Log'!P$5:P$204)) -> 64 | F9: =IF(A9="","",COUNTIFS('Boulder Sample Log'!A$5:A$204,A9,'Boulder Sample Log'!S$5:S$204,"Y")) -> 0 | G9: Rdg 449 (sulphur rock), 451 (90.4s), 452 (1.8s), 461 (no contact/Fe<LOD) | H9: Y | I9: Pass | J9: G07(H+F)+G01(H+F)+G05(H); 5 boulders; no powder; protocol switch 5x3->5x2 per Bartos for low readings; G5 only 1 boulder
A10: 46125 | B10: Sunny Clear, 78F | C10: SWRP + WWRP | D10: =IF(A10="","",COUNTIF('Boulder Sample Log'!A$5:A$204,A10)) -> 7 | E10: =IF(A10="","",SUMIF('Boulder Sample Log'!A$5:A$204,A10,'Boulder Sample Log'!P$5:P$204)) -> 80 | F10: =IF(A10="","",COUNTIFS('Boulder Sample Log'!A$5:A$204,A10,'Boulder Sample Log'!S$5:S$204,"Y")) -> 0 | G10: Rdg 512+516+518 (G2 mishaps), 546 (G3 pre-range), 551 (G3 discarded), 579 (ore rock curiosity shot) | H10: Y | I10: Pass | J10: G09(H)+G02(H)+G08(H+F)+G03(H+F)+G06(H); 7 boulders; 5 grids; no powder; mixed 5x2/5x3 protocol; Michelle Gill ran SWRP, Mo ran WWRP; TP58 boulders at G03; ore rock curiosity shot near G06
A11: 46126 | B11: Cloudy, 50F | C11: WWRP + WRD | D11: =IF(A11="","",COUNTIF('Boulder Sample Log'!A$5:A$204,A11)) -> 7 | E11: =IF(A11="","",SUMIF('Boulder Sample Log'!A$5:A$204,A11,'Boulder Sample Log'!P$5:P$204)) -> 79 | F11: =IF(A11="","",COUNTIFS('Boulder Sample Log'!A$5:A$204,A11,'Boulder Sample Log'!S$5:S$204,"Y")) -> 0 | G11: Rdg 655+665 trigger mishaps; Rdg 662 discarded (104.84s) | H11: Y | I11: Pass | J11: G4(H)+G6(H,H)+G2(F)+G5(H)+G15(H,F); 7 boulders; WWRP effectively complete (G8/G12 inaccessible overgrowth, G10/G11 no surface boulders); WRD started at G15; Michelle Gill operator; G2 B2 F = campaign record Hg (avg 3,702 ppm, single reading 23,796 ppm); 623/645/664 Fe=0 flagged
A12: 46127 | B12: Sunny, clear, 65°F | C12: WRD G14, G13, G11, G10 | D12: =IF(A12="","",COUNTIF('Boulder Sample Log'!A$5:A$204,A12)) -> 6 | E12: =IF(A12="","",SUMIF('Boulder Sample Log'!A$5:A$204,A12,'Boulder Sample Log'!P$5:P$204)) -> 62 | F12: =IF(A12="","",COUNTIFS('Boulder Sample Log'!A$5:A$204,A12,'Boulder Sample Log'!S$5:S$204,"Y")) -> 0 | G12: None | H12: Y | I12: Y | J12: Rdg 730 discarded (Fe<LOD); 1 trigger mishap; 6 boulders across 4 grids
A13: 46128 | B13: Sunny, clear, high wind/gusty, 55-57°F | C13: WRD G10, G12, G9, G8, G7, G6 | D13: =IF(A13="","",COUNTIF('Boulder Sample Log'!A$5:A$204,A13)) -> 10 | E13: =IF(A13="","",SUMIF('Boulder Sample Log'!A$5:A$204,A13,'Boulder Sample Log'!P$5:P$204)) -> 111 | F13: =IF(A13="","",COUNTIFS('Boulder Sample Log'!A$5:A$204,A13,'Boulder Sample Log'!S$5:S$204,"Y")) -> 0 | G13: None | H13: Y | I13: Y | J13: 4 trigger mishaps (748,807,829,840); Rdg 746+834 discarded (Fe<LOD); Rdg 777 Fe<LOD flagged; Hot boulders: G7-B2(F), G8-B2(F), G6-B1(H)
A14: 46129 | B14: Sunny, clear, 65°F | C14: WRD G6, G5, G4, G3, G2 | D14: =IF(A14="","",COUNTIF('Boulder Sample Log'!A$5:A$204,A14)) -> 9 | E14: =IF(A14="","",SUMIF('Boulder Sample Log'!A$5:A$204,A14,'Boulder Sample Log'!P$5:P$204)) -> 99 | F14: =IF(A14="","",COUNTIFS('Boulder Sample Log'!A$5:A$204,A14,'Boulder Sample Log'!S$5:S$204,"Y")) -> 0 | G14: None | H14: Y | I14: Y | J14: Rdg 883, 908, 909, 942 trigger mishaps; Rdg 952 discarded (Fe<LOD, retake at Rdg 955); 9 boulders across 5 grids; Hot: G5-B2(F) Hg 76 ppm avg
A15: 46130 | B15: Sunny, clear, 60°F | C15: WRD G1; DRA G1, G2, G5 | D15: =IF(A15="","",COUNTIF('Boulder Sample Log'!A$5:A$204,A15)) -> 7 | E15: =IF(A15="","",SUMIF('Boulder Sample Log'!A$5:A$204,A15,'Boulder Sample Log'!P$5:P$204)) -> 75 | F15: =IF(A15="","",COUNTIFS('Boulder Sample Log'!A$5:A$204,A15,'Boulder Sample Log'!S$5:S$204,"Y")) -> 0 | G15: None | H15: Y | I15: Y | J15: Rdg 984 discarded (Fe<LOD; retake 985); Rdg 1027 discarded (Fe<LOD; retake 1028); 7 boulders; started DRA (G1, G2, G5); Hot: DRA-G1-B1(H) Hg 111 avg; DRA-G1-B2(F) Hg 47 avg; H2S at DRA pile — Adam relocated to NWRP
... A26: 46150 | B26: Sunny, clear, ~75-80°F | C26: WRD shoreline (depth XRF) + DRA + SWRP (powder collection) + on-site powder XRF | D26: =IF(A26="","",COUNTIF('Boulder Sample Log'!A$5:A$204,A26)) -> 0 | E26: =IF(A26="","",SUMIF('Boulder Sample Log'!A$5:A$204,A26,'Boulder Sample Log'!P$5:P$204)) -> 0 | F26: =IF(A26="","",COUNTIFS('Boulder Sample Log'!A$5:A$204,A26,'Boulder Sample Log'!S$5:S$204,"Y")) -> 0 | G26: X501203 gun clock drift (~14.5 hr behind real); discards captured (1740, 1763, 1783, 1800, 1804, 1814, 1820, 1842, 1851, 729, 788) in field forms | H26: 2 depth NCDs + 1 powder NCD + 2 system check NCDs | I26: Pass (both guns AM+PM) | J26: Day 24 (FINAL). Field team Michelle + Ariel wrapped WRD shoreline depth XRF — 13 boulders profiled across G6-G12 (G7 FB-B2, G8 FB-B2 + HB-B1, G9 HB-B1, G10 HB-B1 + HB-B2, G6 HB-B1 + FB-B2, G11 HB-B1 + HB-B2, G12 HB-B1 + HB-B2). Mo collected final 3 boulder powders (DRA-G01, DRA-G10, SWRP-G08). Powder XRF run on all 14 primary boulder parents (rdgs 756-783, X500456 Mining mode). ERRG demobed: skid steer decon AM, then offsite. Christian + Tyler hauled aggregate to second connex. XRF data collection now complete.
D27: =IF(A27="","",COUNTIF('Boulder Sample Log'!A$5:A$204,A27)) | E27: =IF(A27="","",SUMIF('Boulder Sample Log'!A$5:A$204,A27,'Boulder Sample Log'!P$5:P$204)) | F27: =IF(A27="","",COUNTIFS('Boulder Sample Log'!A$5:A$204,A27,'Boulder Sample Log'!S$5:S$204,"Y"))
D28: =IF(A28="","",COUNTIF('Boulder Sample Log'!A$5:A$204,A28)) | E28: =IF(A28="","",SUMIF('Boulder Sample Log'!A$5:A$204,A28,'Boulder Sample Log'!P$5:P$204)) | F28: =IF(A28="","",COUNTIFS('Boulder Sample Log'!A$5:A$204,A28,'Boulder Sample Log'!S$5:S$204,"Y"))
D29: =IF(A29="","",COUNTIF('Boulder Sample Log'!A$5:A$204,A29)) | E29: =IF(A29="","",SUMIF('Boulder Sample Log'!A$5:A$204,A29,'Boulder Sample Log'!P$5:P$204)) | F29: =IF(A29="","",COUNTIFS('Boulder Sample Log'!A$5:A$204,A29,'Boulder Sample Log'!S$5:S$204,"Y"))
D30: =IF(A30="","",COUNTIF('Boulder Sample Log'!A$5:A$204,A30)) | E30: =IF(A30="","",SUMIF('Boulder Sample Log'!A$5:A$204,A30,'Boulder Sample Log'!P$5:P$204)) | F30: =IF(A30="","",COUNTIFS('Boulder Sample Log'!A$5:A$204,A30,'Boulder Sample Log'!S$5:S$204,"Y"))
D31: =IF(A31="","",COUNTIF('Boulder Sample Log'!A$5:A$204,A31)) | E31: =IF(A31="","",SUMIF('Boulder Sample Log'!A$5:A$204,A31,'Boulder Sample Log'!P$5:P$204)) | F31: =IF(A31="","",COUNTIFS('Boulder Sample Log'!A$5:A$204,A31,'Boulder Sample Log'!S$5:S$204,"Y"))
D32: =IF(A32="","",COUNTIF('Boulder Sample Log'!A$5:A$204,A32)) | E32: =IF(A32="","",SUMIF('Boulder Sample Log'!A$5:A$204,A32,'Boulder Sample Log'!P$5:P$204)) | F32: =IF(A32="","",COUNTIFS('Boulder Sample Log'!A$5:A$204,A32,'Boulder Sample Log'!S$5:S$204,"Y"))
D33: =IF(A33="","",COUNTIF('Boulder Sample Log'!A$5:A$204,A33)) | E33: =IF(A33="","",SUMIF('Boulder Sample Log'!A$5:A$204,A33,'Boulder Sample Log'!P$5:P$204)) | F33: =IF(A33="","",COUNTIFS('Boulder Sample Log'!A$5:A$204,A33,'Boulder Sample Log'!S$5:S$204,"Y"))
D34: =IF(A34="","",COUNTIF('Boulder Sample Log'!A$5:A$204,A34)) | E34: =IF(A34="","",SUMIF('Boulder Sample Log'!A$5:A$204,A34,'Boulder Sample Log'!P$5:P$204)) | F34: =IF(A34="","",COUNTIFS('Boulder Sample Log'!A$5:A$204,A34,'Boulder Sample Log'!S$5:S$204,"Y"))
D35: =IF(A35="","",COUNTIF('Boulder Sample Log'!A$5:A$204,A35)) | E35: =IF(A35="","",SUMIF('Boulder Sample Log'!A$5:A$204,A35,'Boulder Sample Log'!P$5:P$204)) | F35: =IF(A35="","",COUNTIFS('Boulder Sample Log'!A$5:A$204,A35,'Boulder Sample Log'!S$5:S$204,"Y"))
D36: =IF(A36="","",COUNTIF('Boulder Sample Log'!A$5:A$204,A36)) | E36: =IF(A36="","",SUMIF('Boulder Sample Log'!A$5:A$204,A36,'Boulder Sample Log'!P$5:P$204)) | F36: =IF(A36="","",COUNTIFS('Boulder Sample Log'!A$5:A$204,A36,'Boulder Sample Log'!S$5:S$204,"Y"))
D37: =IF(A37="","",COUNTIF('Boulder Sample Log'!A$5:A$204,A37)) | E37: =IF(A37="","",SUMIF('Boulder Sample Log'!A$5:A$204,A37,'Boulder Sample Log'!P$5:P$204)) | F37: =IF(A37="","",COUNTIFS('Boulder Sample Log'!A$5:A$204,A37,'Boulder Sample Log'!S$5:S$204,"Y"))
D38: =IF(A38="","",COUNTIF('Boulder Sample Log'!A$5:A$204,A38)) | E38: =IF(A38="","",SUMIF('Boulder Sample Log'!A$5:A$204,A38,'Boulder Sample Log'!P$5:P$204)) | F38: =IF(A38="","",COUNTIFS('Boulder Sample Log'!A$5:A$204,A38,'Boulder Sample Log'!S$5:S$204,"Y"))
... D53: =IF(A53="","",COUNTIF('Boulder Sample Log'!A$5:A$204,A53)) | E53: =IF(A53="","",SUMIF('Boulder Sample Log'!A$5:A$204,A53,'Boulder Sample Log'!P$5:P$204)) | F53: =IF(A53="","",COUNTIFS('Boulder Sample Log'!A$5:A$204,A53,'Boulder Sample Log'!S$5:S$204,"Y"))

Sheet Grid Completion
A1: SBMM OU1 — XRF Boulder Sampling Grid Completion Tracker
A2: 7 Areas | 15 Grids/Area | 2 Boulders/Grid (1H + 1F) | 210 Total Boulders | Auto-updates from Boulder Sample Log
A3: Area | B3: G01 | C3: G02 | D3: G03 | E3: G04 | F3: G05 | G3: G06 | H3: G07 | I3: G08 | J3: G09 | K3: G10 | L3: G11 | M3: G12 | N3: G13 | O3: G14 | P3: G15 | Q3: Done | R3: Notes
